<?xml version="1.0" encoding="utf-8"?>
<!-- =================================================================================== -->
<!-- |    This document was autogenerated by xacro from ecm_launch.urdf.xacro          | -->
<!-- |    EDITING THIS FILE BY HAND IS NOT RECOMMENDED                                 | -->
<!-- =================================================================================== -->
<robot name="ecm">
    <material name="white">
        <color rgba="0.95 0.95 0.95 1"/>
    </material>
    <material name="grey">
        <color rgba="0.80 0.80 0.80 1"/>
    </material>
    <material name="silver">
        <color rgba="0.8941 0.8941 0.8863 1"/>
    </material>
    <material name="black">
        <color rgba="0.0314 0.0314 0.0314 1"/>
    </material>
    <material name="red_translucent">
        <color rgba="1 0 0 0.5"/>
    </material>

    <!--  <link name="world"/>-->

    <link name="ecm_base_link">
        <inertial>
            <origin rpy="0 0 0" xyz="-0.0048 0 0.0670"/>
            <mass value="2.6363"/>
            <inertia ixx="0" ixy="0" ixz="0" iyy="0" iyz="0" izz="0"/>
        </inertial>
        <visual>
            <origin rpy="0 0 0" xyz="0 0 0"/>
            <geometry>
                <mesh filename="meshes/visual/base_link.obj"/>
            </geometry>
            <material name="white"/>
        </visual>
        <!--    <collision>-->
        <!--      <origin rpy="0 0 0" xyz="0 0 0"/>-->
        <!--      <geometry>-->
        <!--        <mesh filename="meshes/collision/base_link.STL"/>-->
        <!--      </geometry>-->
        <!--    </collision>-->
    </link>

    <link name="ecm_yaw_link">
        <inertial>
            <!-- 0.5394-0.1067 -->
            <origin rpy="3.14159265359 0 1.57079632679" xyz="-0.0290 0 0.4327"/>
            <mass value="6.4168"/>
            <inertia ixx="0.00086598" ixy="0" ixz="0" iyy="0.0016561" iyz="-0.00015825" izz="0.00085001"/>
        </inertial>
        <visual>
            <origin rpy="3.14159265359 0 1.57079632679" xyz="0 0 0.5394"/>
            <geometry>
                <mesh filename="meshes/visual/yaw_link.obj"/>
            </geometry>
            <material name="white"/>
        </visual>
        <!--    <collision>-->
        <!--      <origin rpy="3.14159265359 0 1.57079632679" xyz="0 0 0.5394"/>-->
        <!--      <geometry>-->
        <!--        <mesh filename="meshes/collision/yaw_link.STL"/>-->
        <!--      </geometry>-->
        <!--    </collision>-->
    </link>

    <joint name="ecm_yaw_joint" type="revolute">
        <!-- by jqxu -->
        <origin rpy="0 -1.57079632679 0" xyz="0.6126 0 0.1016"/>
        <parent link="ecm_base_link"/>
        <child link="ecm_yaw_link"/>
        <axis xyz="0 0 1"/>
        <limit effort="100" lower="-1.57079632679" upper="1.57079632679" velocity="2.1"/>
    </joint>

    <link name="ecm_pitch_end_link">
        <inertial>
            <!-- 0.1030-0.0181 0.2868+0.0271 -->
            <origin rpy="0 0 3.14159265359" xyz="0.0849 0.3139 0"/>
            <mass value="2.0321"/>
            <inertia ixx="0" ixy="0" ixz="0" iyy="0" iyz="0" izz="0"/>
        </inertial>
        <visual>
            <origin rpy="0 0 3.14159265359" xyz="0.1030 0.2868 0"/>
            <geometry>
                <mesh filename="meshes/visual/pitch_end_link.STL"/>
            </geometry>
            <material name="black"/>
        </visual>
        <collision>
            <origin rpy="0 0 3.14159265359" xyz="0.1030 0.2868 0"/>
            <geometry>
                <mesh filename="meshes/collision/pitch_end_link.STL"/>
            </geometry>
        </collision>
    </link>

    <joint name="ecm_pitch_end_joint" type="revolute">
        <origin rpy="-1.57079632679 -1.57079632679 0" xyz="0 0 0"/>
        <parent link="ecm_yaw_link"/>
        <child link="ecm_pitch_end_link"/>
        <axis xyz="0 0 1"/>
        <limit effort="100" lower="-0.784" upper="1.158" velocity="2.1"/>
    </joint>

    <link name="ecm_main_insertion_link">
        <inertial>
            <!-- 0.0610-0.0086 0  0.0092-0.0479 -->
            <origin rpy="0 0 3.14159265359" xyz="0.0524 0 -0.0387"/>
            <mass value="0.2311"/>
            <inertia ixx="0" ixy="0" ixz="0" iyy="0" iyz="0" izz="0"/>
        </inertial>
        <visual>
            <origin rpy="0 0 3.14159265359" xyz="0.0610 0 0.0092"/>
            <geometry>
                <mesh filename="meshes/visual/main_insertion_link.STL"/>
            </geometry>
            <material name="black"/>
        </visual>
        <collision>
            <origin rpy="0 0 3.14159265359" xyz="0.0610 0 0.0092"/>
            <geometry>
                <mesh filename="meshes/collision/main_insertion_link.STL"/>
            </geometry>
        </collision>
    </link>

    <joint name="ecm_main_insertion_joint" type="prismatic">
        <origin rpy="1.57079632679 0 0" xyz="0 0.3822 0"/>
        <parent link="ecm_pitch_end_link"/>
        <child link="ecm_main_insertion_link"/>
        <axis xyz="0 0 1"/>
        <limit effort="50" lower="0" upper="0.254" velocity="10"/>
    </joint>

    <link name="ecm_tool_link">
        <inertial>
            <!-- -0.3737-0.1073 -->
            <origin rpy="0 0 3.14159265359" xyz="0 0 -0.4810"/>
            <mass value="1.9074"/>
            <inertia ixx="0" ixy="0" ixz="0" iyy="0" iyz="0" izz="0"/>
        </inertial>
        <visual>
            <origin rpy="0 0 3.14159265359" xyz="0 0 -0.3737"/>
            <geometry>
                <mesh filename="meshes/visual/tool_link_1.obj"/>
            </geometry>
            <material name="silver"/>
        </visual>
        <collision>
            <origin rpy="0 0 3.14159265359" xyz="0 0 -0.3737"/>
            <geometry>
                <mesh filename="meshes/collision/tool_link.STL"/>
            </geometry>
        </collision>
    </link>

    <joint name="ecm_tool_joint" type="revolute">
        <origin rpy="0 0 0" xyz="0 0 0.3829"/>
        <parent link="ecm_main_insertion_link"/>
        <child link="ecm_tool_link"/>
        <axis xyz="0 0 1"/>
        <limit effort="100" lower="-1.57079632679" upper="1.57079632679" velocity="2.1"/>
    </joint>

    <link name="ecm_end_link">
        <inertial>
            <origin rpy="0 0 0" xyz="0 0 0"/>
            <mass value="0"/>
            <inertia ixx="0" ixy="0" ixz="0" iyy="0" iyz="0" izz="0"/>
        </inertial>
    </link>

    <joint name="ecm_end_joint" type="fixed">
        <origin rpy="0 0 0" xyz="0 0 0"/>
        <parent link="ecm_tool_link"/>
        <child link="ecm_end_link"/>
        <axis xyz="0 0 0"/>
    </joint>

    <link name="ecm_tip_link">
        <inertial>
            <origin rpy="0 0 0" xyz="0 0 0"/>
            <mass value="0"/>
            <inertia ixx="0" ixy="0" ixz="0" iyy="0" iyz="0" izz="0"/>
        </inertial>
    </link>

    <joint name="ecm_tip_joint" type="fixed">
        <origin rpy="0 0 -1.57079632679" xyz="0 0 0.02"/>
        <parent link="ecm_tool_link"/>
        <child link="ecm_tip_link"/>
        <axis xyz="0 0 0"/>
    </joint>

    <link name="ecm_pitch_front_link">
        <inertial>
            <origin rpy="0 0 3.14159265359" xyz="0.0306 0.1358 0"/>
            <mass value="1.6069"/>
            <inertia ixx="0" ixy="0" ixz="0" iyy="0" iyz="0" izz="0"/>
        </inertial>
        <visual>
            <origin rpy="0 0 3.14159265359" xyz="0 0 0"/>
            <geometry>
                <mesh filename="meshes/visual/pitch_front_link.STL"/>
            </geometry>
            <material name="black"/>
        </visual>
        <!--    <collision>-->
        <!--      <origin rpy="0 0 3.14159265359" xyz="0 0 0"/>-->
        <!--      <geometry>-->
        <!--        <mesh filename="meshes/collision/pitch_front_link.STL"/>-->
        <!--      </geometry>-->
        <!--    </collision>-->
    </link>

    <joint name="ecm_pitch_front_joint" type="revolute">
        <origin rpy="-1.57079632679 -1.57079632679 0" xyz="0 0 0.3404"/>
        <parent link="ecm_yaw_link"/>
        <child link="ecm_pitch_front_link"/>
        <axis xyz="0 0 1"/>
        <limit effort="100" lower="-0.784" upper="1.158" velocity="2.1"/>
        <mimic joint="ecm_pitch_end_joint" multiplier="1"/>
    </joint>

    <link name="ecm_pitch_bottom_link">
        <inertial>
            <origin rpy="0 0 3.14159265359" xyz="-0.1459 0.0267 0"/>
            <mass value="0.3593"/>
            <inertia ixx="0.00023901" ixy="0.00022767" ixz="0" iyy="0.0030096" iyz="0" izz="0.0029617"/>
        </inertial>
        <visual>
            <origin rpy="0 0 3.14159265359" xyz="0 0 0"/>
            <geometry>
                <mesh filename="meshes/visual/pitch_bottom_link.STL"/>
            </geometry>
            <material name="black"/>
        </visual>
        <!--    <collision>-->
        <!--      <origin rpy="0 0 3.14159265359" xyz="0 0 0"/>-->
        <!--      <geometry>-->
        <!--        <mesh filename="meshes/collision/pitch_bottom_link.STL"/>-->
        <!--      </geometry>-->
        <!--    </collision>-->
    </link>

    <joint name="ecm_pitch_bottom_joint" type="revolute">
        <origin rpy="0 0 0" xyz="0.1030 0.2868 0"/>
        <parent link="ecm_pitch_front_link"/>
        <child link="ecm_pitch_bottom_link"/>
        <axis xyz="0 0 1"/>
        <limit effort="100" lower="-1.158" upper="0.784" velocity="2.1"/>
        <mimic joint="ecm_pitch_end_joint" multiplier="-1"/>
    </joint>

    <link name="ecm_pitch_top_link">
        <inertial>
            <origin rpy="0 0 3.14159265359" xyz="-0.1702 0 0"/>
            <mass value="0.4385"/>
            <inertia ixx="0" ixy="0" ixz="0" iyy="0" iyz="0" izz="0"/>
        </inertial>
        <visual>
            <origin rpy="0 0 3.14159265359" xyz="0 0 0"/>
            <geometry>
                <mesh filename="meshes/visual/pitch_top_link.STL"/>
            </geometry>
            <material name="black"/>
        </visual>
        <!--    <collision>-->
        <!--      <origin rpy="0 0 3.14159265359" xyz="0 0 0"/>-->
        <!--      <geometry>-->
        <!--        <mesh filename="meshes/collision/pitch_top_link.STL"/>-->
        <!--      </geometry>-->
        <!--    </collision>-->
    </link>

    <joint name="ecm_pitch_top_joint" type="revolute">
        <origin rpy="0 0 0" xyz="0.1085 0.3242 0"/>
        <parent link="ecm_pitch_front_link"/>
        <child link="ecm_pitch_top_link"/>
        <axis xyz="0 0 1"/>
        <limit effort="100" lower="-1.158" upper="0.784" velocity="2.1"/>
        <mimic joint="ecm_pitch_end_joint" multiplier="-1"/>
    </joint>

    <link name="ecm_pitch_back_link">
        <inertial>
            <origin rpy="0 0 3.14159265359" xyz="0.0329 0.1500 0"/>
            <mass value="0.4214"/>
            <inertia ixx="0" ixy="0" ixz="0" iyy="0" iyz="0" izz="0"/>
        </inertial>
        <visual>
            <origin rpy="0 0 3.14159265359" xyz="0 0 0"/>
            <geometry>
                <mesh filename="meshes/visual/pitch_back_link.STL"/>
            </geometry>
            <material name="black"/>
        </visual>
        <!--    <collision>-->
        <!--      <origin rpy="0 0 3.14159265359" xyz="0 0 0"/>-->
        <!--      <geometry>-->
        <!--        <mesh filename="meshes/collision/pitch_back_link.STL"/>-->
        <!--      </geometry>-->
        <!--    </collision>-->
    </link>

    <joint name="ecm_pitch_back_joint" type="revolute">
        <origin rpy="-1.57079632679 -1.57079632679 0" xyz="-0.0098 0 0.3770"/>
        <parent link="ecm_yaw_link"/>
        <child link="ecm_pitch_back_link"/>
        <axis xyz="0 0 1"/>
        <limit effort="100" lower="-0.784" upper="1.158" velocity="2.1"/>
        <mimic joint="ecm_pitch_end_joint" multiplier="1"/>
    </joint>

    <link name="ecm_remote_center_link">
        <inertial>
            <origin rpy="0 0 0" xyz="0 0 0"/>
            <mass value="0."/>
            <inertia ixx="0" ixy="0" ixz="0" iyy="0" iyz="0" izz="0"/>
        </inertial>
        <visual>
            <origin rpy="0 0 0" xyz="0 0 0"/>
            <geometry>
                <sphere radius="0.015"/>
            </geometry>
            <material name="red_translucent"/>
        </visual>
    </link>

    <joint name="ecm_remote_center_joint" type="fixed">
        <origin rpy="0 0 -1.57079632679" xyz="0.6126 0 0.1016"/>
        <parent link="ecm_base_link"/>
        <child link="ecm_remote_center_link"/>
        <axis xyz="0 0 0"/>
    </joint>
</robot>
