<?xml version="1.0" encoding="utf-8"?>
<!-- =================================================================================== -->
<!-- |    This document was autogenerated by xacro from ecm_launch.urdf.xacro          | -->
<!-- |    EDITING THIS FILE BY HAND IS NOT RECOMMENDED                                 | -->
<!-- =================================================================================== -->
<robot name="ecm">

    <!--  <link name="world"/>-->

    <link name="ecm_base_link">
        <inertial>
            <origin rpy="0 0 0" xyz="-0.0048227 0 0.068959"/>
            <mass value="2.6363"/>
            <inertia ixx="0" ixy="0" ixz="0" iyy="0" iyz="0" izz="0"/>
        </inertial>
        <visual>
            <origin rpy="0 0 0" xyz="0 0 0"/>
            <geometry>
                <mesh filename="meshes/visual/base_link.STL"/>
            </geometry>
            <material name="">
                <color rgba="0.64706 0.61961 0.58824 1"/>
            </material>
        </visual>
        <collision>
            <origin rpy="0 0 0" xyz="0 0 0"/>
            <geometry>
                <mesh filename="meshes/collision/base_link.STL"/>
            </geometry>
        </collision>
    </link>

    <link name="ecm_yaw_link">
        <inertial>
            <origin rpy="0 0 0" xyz="0 -0.029045 0.10669"/>
            <mass value="6.4168"/>
            <inertia ixx="0.00086598" ixy="0" ixz="0" iyy="0.0016561" iyz="-0.00015825" izz="0.00085001"/>
        </inertial>
        <visual>
            <origin rpy="0 0 0" xyz="0 0 0"/>
            <geometry>
                <mesh filename="meshes/visual/yaw_link.STL"/>
            </geometry>
            <material name="">
                <color rgba="0.64706 0.61961 0.58824 1"/>
            </material>
        </visual>
        <collision>
            <origin rpy="0 0 0" xyz="0 0 0"/>
            <geometry>
                <mesh filename="meshes/collision/yaw_link.STL"/>
            </geometry>
        </collision>
    </link>

    <joint name="ecm_yaw_joint" type="revolute">
        <origin rpy="1.57079632679 0 1.57079632679" xyz="0.0732 0 0.10146"/>
        <parent link="ecm_base_link"/>
        <child link="ecm_yaw_link"/>
        <axis xyz="0 0 1"/>
        <limit effort="1000" lower="-1.595183" upper="1.581733" velocity="10"/>
    </joint>

    <link name="ecm_pitch_front_link">
        <inertial>
            <origin rpy="0 0 0" xyz="-0.030619 -0.13578 0"/>
            <mass value="1.6069"/>
            <inertia ixx="0" ixy="0" ixz="0" iyy="0" iyz="0" izz="0"/>
        </inertial>
        <visual>
            <origin rpy="0 0 0" xyz="0 0 0"/>
            <geometry>
                <mesh filename="meshes/visual/pitch_front_link.STL"/>
            </geometry>
            <material name="">
                <color rgba="0.64706 0.61961 0.58824 1"/>
            </material>
        </visual>
        <collision>
            <origin rpy="0 0 0" xyz="0 0 0"/>
            <geometry>
                <mesh filename="meshes/collision/pitch_front_link.STL"/>
            </geometry>
        </collision>
    </link>

    <joint name="ecm_pitch_front_joint" type="revolute">
        <origin rpy="3.14159265359 -1.57079632679 0" xyz="0 0 0.1990"/>
        <parent link="ecm_yaw_link"/>
        <child link="ecm_pitch_front_link"/>
        <axis xyz="0 0 1"/>
        <limit effort="1000" lower="-0.783710" upper="1.157657" velocity="10"/>
    </joint>

    <link name="ecm_pitch_bottom_link">
        <inertial>
            <origin rpy="0 0 0" xyz="0.14594 -0.026715 -0.00016488"/>
            <mass value="0.35928"/>
            <inertia ixx="0.00023901" ixy="0.00022767" ixz="0" iyy="0.0030096" iyz="0" izz="0.0029617"/>
        </inertial>
        <visual>
            <origin rpy="0 0 0" xyz="0 0 0"/>
            <geometry>
                <mesh filename="meshes/visual/pitch_bottom_link.STL"/>
            </geometry>
            <material name="">
                <color rgba="0.25098 0.25098 0.25098 1"/>
            </material>
        </visual>
        <collision>
            <origin rpy="0 0 0" xyz="0 0 0"/>
            <geometry>
                <mesh filename="meshes/collision/pitch_bottom_link.STL"/>
            </geometry>
        </collision>
    </link>

    <joint name="ecm_pitch_bottom_joint" type="revolute">
        <origin rpy="0 0 0" xyz="-0.1030 -0.2868 0"/>
        <parent link="ecm_pitch_front_link"/>
        <child link="ecm_pitch_bottom_link"/>
        <axis xyz="0 0 1"/>
        <limit effort="1000" lower="-1.157657" upper="0.783710" velocity="10"/>
        <mimic joint="ecm_pitch_front_joint" multiplier="-1"/>
    </joint>

    <link name="ecm_pitch_end_link">
        <inertial>
            <origin rpy="0 0 0" xyz="0.018122 -0.027143 0.00078916"/>
            <mass value="2.0321"/>
            <inertia ixx="0" ixy="0" ixz="0" iyy="0" iyz="0" izz="0"/>
        </inertial>
        <visual>
            <origin rpy="0 0 0" xyz="0 0 0"/>
            <geometry>
                <mesh filename="meshes/visual/pitch_end_link.STL"/>
            </geometry>
            <material name="">
                <color rgba="0.89804 0.91765 0.92941 1"/>
            </material>
        </visual>
        <collision>
            <origin rpy="0 0 0" xyz="0 0 0"/>
            <geometry>
                <mesh filename="meshes/collision/pitch_end_link.STL"/>
            </geometry>
        </collision>
    </link>

    <joint name="ecm_pitch_end_joint" type="revolute">
        <origin rpy="0 0 0" xyz="0.3404 -0.000135620545844151 0"/>
        <parent link="ecm_pitch_bottom_link"/>
        <child link="ecm_pitch_end_link"/>
        <axis xyz="0 0 1"/>
        <limit effort="1000" lower="-0.783710" upper="1.157657" velocity="10"/>
        <mimic joint="ecm_pitch_front_joint" multiplier="1"/>
    </joint>

    <link name="ecm_main_insertion_link">
        <inertial>
            <origin rpy="0 0 0" xyz="0.0086165 -0.00079249 -0.047928"/>
            <mass value="0.23108"/>
            <inertia ixx="0" ixy="0" ixz="0" iyy="0" iyz="0" izz="0"/>
        </inertial>
        <visual>
            <origin rpy="0 0 0" xyz="0 0 0"/>
            <geometry>
                <mesh filename="meshes/visual/main_insertion_link.STL"/>
            </geometry>
            <material name="">
                <color rgba="0.25098 0.25098 0.25098 1"/>
            </material>
        </visual>
        <collision>
            <origin rpy="0 0 0" xyz="0 0 0"/>
            <geometry>
                <mesh filename="meshes/collision/main_insertion_link.STL"/>
            </geometry>
        </collision>
    </link>

    <joint name="ecm_main_insertion_joint" type="prismatic">
        <origin rpy="-1.57079632679 0 0" xyz="0.042 -0.086143 0"/>
        <parent link="ecm_pitch_end_link"/>
        <child link="ecm_main_insertion_link"/>
        <axis xyz="0 0 1"/>
        <limit effort="50" lower="0" upper="0.254193" velocity="100"/>
    </joint>

    <link name="ecm_tool_link">
        <inertial>
            <origin rpy="0 0 0" xyz="0 -0.0007925 -0.10732"/>
            <mass value="1.9074"/>
            <inertia ixx="0" ixy="0" ixz="0" iyy="0" iyz="0" izz="0"/>
        </inertial>
        <visual>
            <origin rpy="0 0 0" xyz="0 0 0"/>
            <geometry>
                <mesh filename="meshes/visual/tool_link.STL"/>
            </geometry>
            <material name="">
                <color rgba="0.75294 0.75294 0.75294 1"/>
            </material>
        </visual>
        <collision>
            <origin rpy="0 0 0" xyz="0 0 0"/>
            <geometry>
                <mesh filename="meshes/collision/tool_link.STL"/>
            </geometry>
        </collision>
    </link>

    <joint name="ecm_tool_joint" type="revolute">
        <origin rpy="0 0 0" xyz="0.0610 0 0"/>
        <parent link="ecm_main_insertion_link"/>
        <child link="ecm_tool_link"/>
        <axis xyz="0 0 -1"/>
        <limit effort="1000" lower="-1.552676" upper="1.566741" velocity="10"/>
    </joint>

    <link name="ecm_pitch_top_link">
        <inertial>
            <origin rpy="0 0 0" xyz="0.1702 0 0.0007925"/>
            <mass value="0.43851"/>
            <inertia ixx="0" ixy="0" ixz="0" iyy="0" iyz="0" izz="0"/>
        </inertial>
        <visual>
            <origin rpy="0 0 0" xyz="0 0 0"/>
            <geometry>
                <mesh filename="meshes/visual/pitch_top_link.STL"/>
            </geometry>
            <material name="">
                <color rgba="0.64706 0.51765 0 1"/>
            </material>
        </visual>
        <collision>
            <origin rpy="0 0 0" xyz="0 0 0"/>
            <geometry>
                <mesh filename="meshes/collision/pitch_top_link.STL"/>
            </geometry>
        </collision>
    </link>

    <joint name="ecm_pitch_top_joint" type="revolute">
        <origin rpy="0 0 0" xyz="-0.10847228839493 -0.324257434492051 0"/>
        <parent link="ecm_pitch_front_link"/>
        <child link="ecm_pitch_top_link"/>
        <axis xyz="0 0 1"/>
        <limit effort="1000" lower="-1.157657" upper="0.783710" velocity="10"/>
        <mimic joint="ecm_pitch_front_joint" multiplier="-1"/>
    </joint>

    <link name="ecm_pitch_back_link">
        <inertial>
            <origin rpy="0 0 0" xyz="-0.032853 -0.14997 -0.0080613"/>
            <mass value="0.4214"/>
            <inertia ixx="0" ixy="0" ixz="0" iyy="0" iyz="0" izz="0"/>
        </inertial>
        <visual>
            <origin rpy="0 0 0" xyz="0 0 0"/>
            <geometry>
                <mesh filename="meshes/visual/pitch_back_link.STL"/>
            </geometry>
            <material name="">
                <color rgba="0.64706 0.51765 0 1"/>
            </material>
        </visual>
        <collision>
            <origin rpy="0 0 0" xyz="0 0 0"/>
            <geometry>
                <mesh filename="meshes/collision/pitch_back_link.STL"/>
            </geometry>
        </collision>
    </link>

    <joint name="ecm_pitch_back_joint" type="revolute">
        <origin rpy="3.14159265359 -1.57079632679 0" xyz="0 -0.0098 0.16243"/>
        <parent link="ecm_yaw_link"/>
        <child link="ecm_pitch_back_link"/>
        <axis xyz="0 0 1"/>
        <limit effort="1000" lower="-0.783710" upper="1.157657" velocity="10"/>
        <mimic joint="ecm_pitch_front_joint" multiplier="1"/>
    </joint>

    <link name="ecm_remote_center_link">
        <inertial>
            <origin rpy="0 0 0" xyz="0 0 0"/>
            <mass value="0.004482"/>
            <inertia ixx="0" ixy="0" ixz="0" iyy="0" iyz="0" izz="0"/>
        </inertial>
        <visual>
            <origin rpy="0 0 0" xyz="0 0 0"/>
            <geometry>
                <mesh filename="meshes/visual/remote_center_link.STL"/>
            </geometry>
            <material name="">
                <color rgba="1 1 1 1"/>
            </material>
        </visual>
        <collision>
            <origin rpy="0 0 0" xyz="0 0 0"/>
            <geometry>
                <mesh filename="meshes/collision/remote_center_link.STL"/>
            </geometry>
        </collision>
    </link>

    <joint name="ecm_remote_center_joint" type="fixed">
        <origin rpy="0 0 -1.57079632679" xyz="0.6126 0 0.1016"/>
        <parent link="ecm_base_link"/>
        <child link="ecm_remote_center_link"/>
        <axis xyz="0 0 0"/>
    </joint>

    <link name="ecm_end_link"/>

    <joint name="ecm_end_joint" type="fixed">
        <origin rpy="0 0 0" xyz="0 0 0.37364"/>
        <parent link="ecm_tool_link"/>
        <child link="ecm_end_link"/>
        <axis xyz="0 0 0"/>
    </joint>
</robot>
